[2024-11-03T23:44:26.763+0000] {taskinstance.py:1157} INFO - Dependencies all met for dep_context=non-requeueable deps ti=<TaskInstance: user_pipeline.extract_users scheduled__2024-11-01T00:00:00+00:00 [queued]>
[2024-11-03T23:44:26.770+0000] {taskinstance.py:1157} INFO - Dependencies all met for dep_context=requeueable deps ti=<TaskInstance: user_pipeline.extract_users scheduled__2024-11-01T00:00:00+00:00 [queued]>
[2024-11-03T23:44:26.770+0000] {taskinstance.py:1359} INFO - Starting attempt 1 of 2
[2024-11-03T23:44:26.781+0000] {taskinstance.py:1380} INFO - Executing <Task(PythonOperator): extract_users> on 2024-11-01 00:00:00+00:00
[2024-11-03T23:44:26.784+0000] {standard_task_runner.py:57} INFO - Started process 62 to run task
[2024-11-03T23:44:26.787+0000] {standard_task_runner.py:84} INFO - Running: ['***', 'tasks', 'run', 'user_pipeline', 'extract_users', 'scheduled__2024-11-01T00:00:00+00:00', '--job-id', '810', '--raw', '--subdir', 'DAGS_FOLDER/user_pipeline.py', '--cfg-path', '/tmp/tmpaobsl7ez']
[2024-11-03T23:44:26.788+0000] {standard_task_runner.py:85} INFO - Job 810: Subtask extract_users
[2024-11-03T23:44:26.827+0000] {task_command.py:415} INFO - Running <TaskInstance: user_pipeline.extract_users scheduled__2024-11-01T00:00:00+00:00 [running]> on host aa6419ae5165
[2024-11-03T23:44:26.897+0000] {taskinstance.py:1660} INFO - Exporting env vars: AIRFLOW_CTX_DAG_OWNER='***' AIRFLOW_CTX_DAG_ID='user_pipeline' AIRFLOW_CTX_TASK_ID='extract_users' AIRFLOW_CTX_EXECUTION_DATE='2024-11-01T00:00:00+00:00' AIRFLOW_CTX_TRY_NUMBER='1' AIRFLOW_CTX_DAG_RUN_ID='scheduled__2024-11-01T00:00:00+00:00'
[2024-11-03T23:44:26.899+0000] {taskinstance.py:1935} ERROR - Task failed with exception
Traceback (most recent call last):
  File "/home/airflow/.local/lib/python3.8/site-packages/airflow/operators/python.py", line 192, in execute
    return_value = self.execute_callable()
  File "/home/airflow/.local/lib/python3.8/site-packages/airflow/operators/python.py", line 209, in execute_callable
    return self.python_callable(*self.op_args, **self.op_kwargs)
  File "/opt/airflow/dags/user_pipeline.py", line 13, in extract_users
    conn = psycopg2.connect(
  File "/home/airflow/.local/lib/python3.8/site-packages/psycopg2/__init__.py", line 122, in connect
    conn = _connect(dsn, connection_factory=connection_factory, **kwasync)
psycopg2.OperationalError: connection to server at "postgres" (172.18.0.3), port 5432 failed: fe_sendauth: no password supplied

[2024-11-03T23:44:26.905+0000] {taskinstance.py:1398} INFO - Marking task as UP_FOR_RETRY. dag_id=user_pipeline, task_id=extract_users, execution_date=20241101T000000, start_date=20241103T234426, end_date=20241103T234426
[2024-11-03T23:44:26.919+0000] {standard_task_runner.py:104} ERROR - Failed to execute job 810 for task extract_users (connection to server at "postgres" (172.18.0.3), port 5432 failed: fe_sendauth: no password supplied
; 62)
[2024-11-03T23:44:26.925+0000] {local_task_job_runner.py:228} INFO - Task exited with return code 1
[2024-11-03T23:44:26.944+0000] {taskinstance.py:2776} INFO - 0 downstream tasks scheduled from follow-on schedule check
