[2024-10-31T20:13:24.314+0000] {taskinstance.py:1157} INFO - Dependencies all met for dep_context=non-requeueable deps ti=<TaskInstance: user_pipeline.extract_users scheduled__2023-11-20T00:00:00+00:00 [queued]>
[2024-10-31T20:13:24.319+0000] {taskinstance.py:1157} INFO - Dependencies all met for dep_context=requeueable deps ti=<TaskInstance: user_pipeline.extract_users scheduled__2023-11-20T00:00:00+00:00 [queued]>
[2024-10-31T20:13:24.319+0000] {taskinstance.py:1359} INFO - Starting attempt 2 of 2
[2024-10-31T20:13:24.329+0000] {taskinstance.py:1380} INFO - Executing <Task(PythonOperator): extract_users> on 2023-11-20 00:00:00+00:00
[2024-10-31T20:13:24.332+0000] {standard_task_runner.py:57} INFO - Started process 2657 to run task
[2024-10-31T20:13:24.334+0000] {standard_task_runner.py:84} INFO - Running: ['***', 'tasks', 'run', 'user_pipeline', 'extract_users', 'scheduled__2023-11-20T00:00:00+00:00', '--job-id', '126', '--raw', '--subdir', 'DAGS_FOLDER/user_pipeline.py', '--cfg-path', '/tmp/tmpds6vxcxi']
[2024-10-31T20:13:24.335+0000] {standard_task_runner.py:85} INFO - Job 126: Subtask extract_users
[2024-10-31T20:13:24.366+0000] {task_command.py:415} INFO - Running <TaskInstance: user_pipeline.extract_users scheduled__2023-11-20T00:00:00+00:00 [running]> on host fcfef3d82597
[2024-10-31T20:13:24.416+0000] {taskinstance.py:1660} INFO - Exporting env vars: AIRFLOW_CTX_DAG_OWNER='***' AIRFLOW_CTX_DAG_ID='user_pipeline' AIRFLOW_CTX_TASK_ID='extract_users' AIRFLOW_CTX_EXECUTION_DATE='2023-11-20T00:00:00+00:00' AIRFLOW_CTX_TRY_NUMBER='2' AIRFLOW_CTX_DAG_RUN_ID='scheduled__2023-11-20T00:00:00+00:00'
[2024-10-31T20:13:24.418+0000] {taskinstance.py:1935} ERROR - Task failed with exception
Traceback (most recent call last):
  File "/home/airflow/.local/lib/python3.8/site-packages/airflow/operators/python.py", line 192, in execute
    return_value = self.execute_callable()
  File "/home/airflow/.local/lib/python3.8/site-packages/airflow/operators/python.py", line 209, in execute_callable
    return self.python_callable(*self.op_args, **self.op_kwargs)
  File "/opt/airflow/dags/user_pipeline.py", line 8, in extract_users
    conn = psycopg2.connect(
  File "/home/airflow/.local/lib/python3.8/site-packages/psycopg2/__init__.py", line 122, in connect
    conn = _connect(dsn, connection_factory=connection_factory, **kwasync)
psycopg2.OperationalError: connection to server at "postgres" (172.18.0.3), port 5432 failed: FATAL:  database "***_db" does not exist

[2024-10-31T20:13:24.423+0000] {taskinstance.py:1398} INFO - Marking task as FAILED. dag_id=user_pipeline, task_id=extract_users, execution_date=20231120T000000, start_date=20241031T201324, end_date=20241031T201324
[2024-10-31T20:13:24.432+0000] {standard_task_runner.py:104} ERROR - Failed to execute job 126 for task extract_users (connection to server at "postgres" (172.18.0.3), port 5432 failed: FATAL:  database "***_db" does not exist
; 2657)
[2024-10-31T20:13:24.471+0000] {local_task_job_runner.py:228} INFO - Task exited with return code 1
[2024-10-31T20:13:24.494+0000] {taskinstance.py:2776} INFO - 0 downstream tasks scheduled from follow-on schedule check
