[2024-11-04T12:48:58.802+0000] {taskinstance.py:1157} INFO - Dependencies all met for dep_context=non-requeueable deps ti=<TaskInstance: user_pipeline.load_users manual__2024-11-04T12:43:55+00:00 [queued]>
[2024-11-04T12:48:58.809+0000] {taskinstance.py:1157} INFO - Dependencies all met for dep_context=requeueable deps ti=<TaskInstance: user_pipeline.load_users manual__2024-11-04T12:43:55+00:00 [queued]>
[2024-11-04T12:48:58.810+0000] {taskinstance.py:1359} INFO - Starting attempt 2 of 2
[2024-11-04T12:48:58.820+0000] {taskinstance.py:1380} INFO - Executing <Task(PythonOperator): load_users> on 2024-11-04 12:43:55+00:00
[2024-11-04T12:48:58.826+0000] {standard_task_runner.py:57} INFO - Started process 183 to run task
[2024-11-04T12:48:58.829+0000] {standard_task_runner.py:84} INFO - Running: ['***', 'tasks', 'run', 'user_pipeline', 'load_users', 'manual__2024-11-04T12:43:55+00:00', '--job-id', '835', '--raw', '--subdir', 'DAGS_FOLDER/user_pipeline.py', '--cfg-path', '/tmp/tmp2jpiyoy2']
[2024-11-04T12:48:58.829+0000] {standard_task_runner.py:85} INFO - Job 835: Subtask load_users
[2024-11-04T12:48:58.866+0000] {task_command.py:415} INFO - Running <TaskInstance: user_pipeline.load_users manual__2024-11-04T12:43:55+00:00 [running]> on host 73f28de08407
[2024-11-04T12:48:58.932+0000] {taskinstance.py:1660} INFO - Exporting env vars: AIRFLOW_CTX_DAG_OWNER='***' AIRFLOW_CTX_DAG_ID='user_pipeline' AIRFLOW_CTX_TASK_ID='load_users' AIRFLOW_CTX_EXECUTION_DATE='2024-11-04T12:43:55+00:00' AIRFLOW_CTX_TRY_NUMBER='2' AIRFLOW_CTX_DAG_RUN_ID='manual__2024-11-04T12:43:55+00:00'
[2024-11-04T12:48:58.935+0000] {taskinstance.py:1935} ERROR - Task failed with exception
Traceback (most recent call last):
  File "/home/airflow/.local/lib/python3.8/site-packages/airflow/operators/python.py", line 192, in execute
    return_value = self.execute_callable()
  File "/home/airflow/.local/lib/python3.8/site-packages/airflow/operators/python.py", line 209, in execute_callable
    return self.python_callable(*self.op_args, **self.op_kwargs)
  File "/opt/airflow/dags/user_pipeline.py", line 63, in load_users
    cursor.execute(insert_query, (user['id'], user['full_name'], user['email'], user['age']))
TypeError: string indices must be integers
[2024-11-04T12:48:58.940+0000] {taskinstance.py:1398} INFO - Marking task as FAILED. dag_id=user_pipeline, task_id=load_users, execution_date=20241104T124355, start_date=20241104T124858, end_date=20241104T124858
[2024-11-04T12:48:58.950+0000] {standard_task_runner.py:104} ERROR - Failed to execute job 835 for task load_users (string indices must be integers; 183)
[2024-11-04T12:48:58.961+0000] {local_task_job_runner.py:228} INFO - Task exited with return code 1
[2024-11-04T12:48:58.972+0000] {taskinstance.py:2776} INFO - 0 downstream tasks scheduled from follow-on schedule check
