[2024-11-04T12:31:04.674+0000] {taskinstance.py:1157} INFO - Dependencies all met for dep_context=non-requeueable deps ti=<TaskInstance: user_pipeline.transform_users manual__2024-11-04T12:26:02+00:00 [queued]>
[2024-11-04T12:31:04.679+0000] {taskinstance.py:1157} INFO - Dependencies all met for dep_context=requeueable deps ti=<TaskInstance: user_pipeline.transform_users manual__2024-11-04T12:26:02+00:00 [queued]>
[2024-11-04T12:31:04.680+0000] {taskinstance.py:1359} INFO - Starting attempt 2 of 2
[2024-11-04T12:31:04.689+0000] {taskinstance.py:1380} INFO - Executing <Task(PythonOperator): transform_users> on 2024-11-04 12:26:02+00:00
[2024-11-04T12:31:04.694+0000] {standard_task_runner.py:57} INFO - Started process 180 to run task
[2024-11-04T12:31:04.696+0000] {standard_task_runner.py:84} INFO - Running: ['***', 'tasks', 'run', 'user_pipeline', 'transform_users', 'manual__2024-11-04T12:26:02+00:00', '--job-id', '829', '--raw', '--subdir', 'DAGS_FOLDER/user_pipeline.py', '--cfg-path', '/tmp/tmpaf_gis8t']
[2024-11-04T12:31:04.697+0000] {standard_task_runner.py:85} INFO - Job 829: Subtask transform_users
[2024-11-04T12:31:04.729+0000] {task_command.py:415} INFO - Running <TaskInstance: user_pipeline.transform_users manual__2024-11-04T12:26:02+00:00 [running]> on host 56089de777d4
[2024-11-04T12:31:04.783+0000] {taskinstance.py:1660} INFO - Exporting env vars: AIRFLOW_CTX_DAG_OWNER='***' AIRFLOW_CTX_DAG_ID='user_pipeline' AIRFLOW_CTX_TASK_ID='transform_users' AIRFLOW_CTX_EXECUTION_DATE='2024-11-04T12:26:02+00:00' AIRFLOW_CTX_TRY_NUMBER='2' AIRFLOW_CTX_DAG_RUN_ID='manual__2024-11-04T12:26:02+00:00'
[2024-11-04T12:31:04.784+0000] {taskinstance.py:1935} ERROR - Task failed with exception
Traceback (most recent call last):
  File "/home/airflow/.local/lib/python3.8/site-packages/airflow/operators/python.py", line 192, in execute
    return_value = self.execute_callable()
  File "/home/airflow/.local/lib/python3.8/site-packages/airflow/operators/python.py", line 209, in execute_callable
    return self.python_callable(*self.op_args, **self.op_kwargs)
  File "/opt/airflow/dags/user_pipeline.py", line 38, in transform_users
    'full_name': user[1],
IndexError: string index out of range
[2024-11-04T12:31:04.788+0000] {taskinstance.py:1398} INFO - Marking task as FAILED. dag_id=user_pipeline, task_id=transform_users, execution_date=20241104T122602, start_date=20241104T123104, end_date=20241104T123104
[2024-11-04T12:31:04.796+0000] {standard_task_runner.py:104} ERROR - Failed to execute job 829 for task transform_users (string index out of range; 180)
[2024-11-04T12:31:04.829+0000] {local_task_job_runner.py:228} INFO - Task exited with return code 1
[2024-11-04T12:31:04.847+0000] {taskinstance.py:2776} INFO - 0 downstream tasks scheduled from follow-on schedule check
