[2024-11-04T10:38:01.814+0000] {taskinstance.py:1157} INFO - Dependencies all met for dep_context=non-requeueable deps ti=<TaskInstance: user_pipeline.extract_users manual__2024-11-04T10:37:58.816730+00:00 [queued]>
[2024-11-04T10:38:01.820+0000] {taskinstance.py:1157} INFO - Dependencies all met for dep_context=requeueable deps ti=<TaskInstance: user_pipeline.extract_users manual__2024-11-04T10:37:58.816730+00:00 [queued]>
[2024-11-04T10:38:01.820+0000] {taskinstance.py:1359} INFO - Starting attempt 1 of 2
[2024-11-04T10:38:01.830+0000] {taskinstance.py:1380} INFO - Executing <Task(PythonOperator): extract_users> on 2024-11-04 10:37:58.816730+00:00
[2024-11-04T10:38:01.833+0000] {standard_task_runner.py:57} INFO - Started process 904 to run task
[2024-11-04T10:38:01.835+0000] {standard_task_runner.py:84} INFO - Running: ['***', 'tasks', 'run', 'user_pipeline', 'extract_users', 'manual__2024-11-04T10:37:58.816730+00:00', '--job-id', '817', '--raw', '--subdir', 'DAGS_FOLDER/user_pipeline.py', '--cfg-path', '/tmp/tmpbo_qgnho']
[2024-11-04T10:38:01.836+0000] {standard_task_runner.py:85} INFO - Job 817: Subtask extract_users
[2024-11-04T10:38:01.872+0000] {task_command.py:415} INFO - Running <TaskInstance: user_pipeline.extract_users manual__2024-11-04T10:37:58.816730+00:00 [running]> on host ed54170a1328
[2024-11-04T10:38:01.936+0000] {taskinstance.py:1660} INFO - Exporting env vars: AIRFLOW_CTX_DAG_OWNER='***' AIRFLOW_CTX_DAG_ID='user_pipeline' AIRFLOW_CTX_TASK_ID='extract_users' AIRFLOW_CTX_EXECUTION_DATE='2024-11-04T10:37:58.816730+00:00' AIRFLOW_CTX_TRY_NUMBER='1' AIRFLOW_CTX_DAG_RUN_ID='manual__2024-11-04T10:37:58.816730+00:00'
[2024-11-04T10:38:01.939+0000] {taskinstance.py:1935} ERROR - Task failed with exception
Traceback (most recent call last):
  File "/home/airflow/.local/lib/python3.8/site-packages/airflow/operators/python.py", line 192, in execute
    return_value = self.execute_callable()
  File "/home/airflow/.local/lib/python3.8/site-packages/airflow/operators/python.py", line 209, in execute_callable
    return self.python_callable(*self.op_args, **self.op_kwargs)
  File "/opt/airflow/dags/user_pipeline.py", line 13, in extract_users
    conn = psycopg2.connect(
  File "/home/airflow/.local/lib/python3.8/site-packages/psycopg2/__init__.py", line 122, in connect
    conn = _connect(dsn, connection_factory=connection_factory, **kwasync)
psycopg2.OperationalError: connection to server at "postgres" (172.18.0.3), port 5432 failed: fe_sendauth: no password supplied

[2024-11-04T10:38:01.945+0000] {taskinstance.py:1398} INFO - Marking task as UP_FOR_RETRY. dag_id=user_pipeline, task_id=extract_users, execution_date=20241104T103758, start_date=20241104T103801, end_date=20241104T103801
[2024-11-04T10:38:01.957+0000] {standard_task_runner.py:104} ERROR - Failed to execute job 817 for task extract_users (connection to server at "postgres" (172.18.0.3), port 5432 failed: fe_sendauth: no password supplied
; 904)
[2024-11-04T10:38:01.968+0000] {local_task_job_runner.py:228} INFO - Task exited with return code 1
[2024-11-04T10:38:01.984+0000] {taskinstance.py:2776} INFO - 0 downstream tasks scheduled from follow-on schedule check
