[2024-10-31T20:47:38.266+0000] {taskinstance.py:1157} INFO - Dependencies all met for dep_context=non-requeueable deps ti=<TaskInstance: user_pipeline.extract_users scheduled__2024-03-23T00:00:00+00:00 [queued]>
[2024-10-31T20:47:38.272+0000] {taskinstance.py:1157} INFO - Dependencies all met for dep_context=requeueable deps ti=<TaskInstance: user_pipeline.extract_users scheduled__2024-03-23T00:00:00+00:00 [queued]>
[2024-10-31T20:47:38.272+0000] {taskinstance.py:1359} INFO - Starting attempt 1 of 2
[2024-10-31T20:47:38.283+0000] {taskinstance.py:1380} INFO - Executing <Task(PythonOperator): extract_users> on 2024-03-23 00:00:00+00:00
[2024-10-31T20:47:38.287+0000] {standard_task_runner.py:57} INFO - Started process 7542 to run task
[2024-10-31T20:47:38.288+0000] {standard_task_runner.py:84} INFO - Running: ['***', 'tasks', 'run', 'user_pipeline', 'extract_users', 'scheduled__2024-03-23T00:00:00+00:00', '--job-id', '345', '--raw', '--subdir', 'DAGS_FOLDER/user_pipeline.py', '--cfg-path', '/tmp/tmp70citgcl']
[2024-10-31T20:47:38.289+0000] {standard_task_runner.py:85} INFO - Job 345: Subtask extract_users
[2024-10-31T20:47:38.324+0000] {task_command.py:415} INFO - Running <TaskInstance: user_pipeline.extract_users scheduled__2024-03-23T00:00:00+00:00 [running]> on host fcfef3d82597
[2024-10-31T20:47:38.383+0000] {taskinstance.py:1660} INFO - Exporting env vars: AIRFLOW_CTX_DAG_OWNER='***' AIRFLOW_CTX_DAG_ID='user_pipeline' AIRFLOW_CTX_TASK_ID='extract_users' AIRFLOW_CTX_EXECUTION_DATE='2024-03-23T00:00:00+00:00' AIRFLOW_CTX_TRY_NUMBER='1' AIRFLOW_CTX_DAG_RUN_ID='scheduled__2024-03-23T00:00:00+00:00'
[2024-10-31T20:47:38.386+0000] {taskinstance.py:1935} ERROR - Task failed with exception
Traceback (most recent call last):
  File "/home/airflow/.local/lib/python3.8/site-packages/airflow/operators/python.py", line 192, in execute
    return_value = self.execute_callable()
  File "/home/airflow/.local/lib/python3.8/site-packages/airflow/operators/python.py", line 209, in execute_callable
    return self.python_callable(*self.op_args, **self.op_kwargs)
  File "/opt/airflow/dags/user_pipeline.py", line 8, in extract_users
    conn = psycopg2.connect(
  File "/home/airflow/.local/lib/python3.8/site-packages/psycopg2/__init__.py", line 122, in connect
    conn = _connect(dsn, connection_factory=connection_factory, **kwasync)
psycopg2.OperationalError: connection to server at "postgres" (172.18.0.3), port 5432 failed: FATAL:  database "***_db" does not exist

[2024-10-31T20:47:38.391+0000] {taskinstance.py:1398} INFO - Marking task as UP_FOR_RETRY. dag_id=user_pipeline, task_id=extract_users, execution_date=20240323T000000, start_date=20241031T204738, end_date=20241031T204738
[2024-10-31T20:47:38.400+0000] {standard_task_runner.py:104} ERROR - Failed to execute job 345 for task extract_users (connection to server at "postgres" (172.18.0.3), port 5432 failed: FATAL:  database "***_db" does not exist
; 7542)
[2024-10-31T20:47:38.430+0000] {local_task_job_runner.py:228} INFO - Task exited with return code 1
[2024-10-31T20:47:38.453+0000] {taskinstance.py:2776} INFO - 0 downstream tasks scheduled from follow-on schedule check
